<?xml version="1.0"?>
<robot name="aubot" xmlns:xacro="http://www.ros.org/wiki/xacro">



  <link name="base_footprint"/>

  <!-- base  -->
  <link name="base_link">
    <visual>
      <geometry>
        <cylinder radius="0.2" length="0.005"/>
      </geometry>
      <material name="black">
        <color rgba="0 0 0 1"/>
      </material>
    </visual>
    <collision>
      <geometry>
        <cylinder radius="0.2" length="0.005"/>
      </geometry>
    </collision>
    <inertial>
      <mass value="1.5"/>
      <origin xyz="0 0 0.0025" rpy="0 0 0"/>
      <inertia ixx="0.01" ixy="0" ixz="0" iyy="0.01" iyz="0" izz="0.02"/>
    </inertial>
  </link>

  <!-- rueda izquierda-->
  <link name="left_wheel">
    <visual>
      <geometry>
        <cylinder radius="0.08" length="0.02"/>
      </geometry>
      <origin xyz="0 0 0" rpy="1.5708 0 0"/>
      <material name="black"/>
    </visual>
    <collision>
      <geometry>
        <cylinder radius="0.08" length="0.02"/>
      </geometry>
      <origin xyz="0 0 0" rpy="1.5708 0 0"/>
    </collision>
    <inertial>
      <mass value="0.2"/>
      <origin xyz="0 0 0" rpy="0 0 0"/>
      <inertia ixx="0.0001" ixy="0" ixz="0" iyy="0.0002" iyz="0" izz="0.0001"/>
    </inertial>
  </link>

  <!-- rueda derecha-->
  <link name="right_wheel">
    <visual>
      <geometry>
        <cylinder radius="0.08" length="0.02"/>
      </geometry>
      <origin xyz="0 0 0" rpy="1.5708 0 0"/>
      <material name="black"/>
    </visual>
    <collision>
      <geometry>
        <cylinder radius="0.08" length="0.02"/>
      </geometry>
      <origin xyz="0 0 0" rpy="1.5708 0 0"/>
    </collision>
    <inertial>
      <mass value="0.2"/>
      <origin xyz="0 0 0" rpy="0 0 0"/>
      <inertia ixx="0.0001" ixy="0" ixz="0" iyy="0.0002" iyz="0" izz="0.0001"/>
    </inertial>
  </link>

  <!-- sensor -->
  <link name="top_sensor">
    <visual>
      <geometry>
        <cylinder radius="0.04" length="0.05"/>
      </geometry>
      <origin xyz="0 0 0.04" rpy="0 0 0"/>
      <material name="blue">
        <color rgba="0 0 1 1"/>
      </material>
    </visual>
    <collision>
      <geometry>
        <cylinder radius="0.04" length="0.05"/>
      </geometry>
    </collision>
    <inertial>
      <mass value="0.1"/>
      <origin xyz="0 0 0.04" rpy="0 0 0"/>
      <inertia ixx="0.00005" ixy="0" ixz="0" iyy="0.00005" iyz="0" izz="0.0001"/>
    </inertial>
  </link>

  <!-- soporte -->
  <link name="rear_support_1">
    <visual>
      <geometry>
        <box size="0.04 0.04 0.01"/>
      </geometry>
      <origin xyz="0 0 0" rpy="0 0 0"/>
      <material name="black"/>
    </visual>
    <collision>
      <geometry>
        <box size="0.04 0.04 0.01"/>
      </geometry>
    </collision>
    <inertial>
      <mass value="0.05"/>
      <origin xyz="0 0 0" rpy="0 0 0"/>
      <inertia ixx="0.00001" ixy="0" ixz="0" iyy="0.00001" iyz="0" izz="0.00001"/>
    </inertial>
  </link>

    <link name="rear_support_2">
    <visual>
      <geometry>
        <box size="0.04 0.04 0.01"/>
      </geometry>
      <origin xyz="0 0 0" rpy="0 0 0"/>
      <material name="black"/>
    </visual>
    <collision>
      <geometry>
        <box size="0.04 0.04 0.01"/>
      </geometry>
    </collision>
    <inertial>
      <mass value="0.05"/>
      <origin xyz="0 0 0" rpy="0 0 0"/>
      <inertia ixx="0.00001" ixy="0" ixz="0" iyy="0.00001" iyz="0" izz="0.00001"/>
    </inertial>
  </link>

  <!-- joints -->
  <joint name="left_wheel_joint" type="continuous">
    <parent link="base_link"/>
    <child link="left_wheel"/>
    <origin xyz="0 0.2 0.0" rpy="0 0 0"/>
    <axis xyz="0 1 0"/>
  </joint>

  <joint name="right_wheel_joint" type="continuous">
    <parent link="base_link"/>
    <child link="right_wheel"/>
    <origin xyz="0 -0.2 0.0" rpy="0 0 0"/>
    <axis xyz="0 1 0"/>
  </joint>

  <joint name="top_sensor_joint" type="fixed">
    <parent link="base_link"/>
    <child link="top_sensor"/>
    <origin xyz="0 0 0.0425" rpy="0 0 0"/>
  </joint>

  <joint name="rear_support_joint_1" type="fixed">
    <parent link="base_link"/>
    <child link="rear_support_1"/>
    <origin xyz="-0.15 0 -0.07" rpy="0 0 0"/>
  </joint>
  <joint name="rear_support_joint_2" type="fixed">
    <parent link="base_link"/>
    <child link="rear_support_2"/>
    <origin xyz="0.15 0 -0.07" rpy="0 0 0"/>
  </joint>

  <joint name="base_joint" type="fixed">
    <parent link="base_footprint"/>
    <child link="base_link" />
    <origin xyz="0 0 0.08" rpy="0 0 0"/>
  </joint>



    <!-- plugins para gazebo -->
 <gazebo>
    <plugin name="differential_drive_controller" filename="libgazebo_ros_diff_drive.so">

      <alwaysOn>true</alwaysOn>
      <updateRate>50</updateRate>
      <leftJoint>left_wheel_joint</leftJoint>
      <rightJoint>right_wheel_joint</rightJoint>
      <wheelSeparation>0.064</wheelSeparation>
      <wheelDiameter>0.032</wheelDiameter>
      <wheelAcceleration>0.1</wheelAcceleration>
      <wheelTorque>10</wheelTorque>
      <commandTopic>cmd_vel</commandTopic>
      <odometryTopic>odom</odometryTopic>
      <odometryFrame>odom</odometryFrame>
      <odometrySource>world</odometrySource>
      <robotBaseFrame>base_footprint</robotBaseFrame>
      <publishTf>true</publishTf>
      <publishOdomTF>true</publishOdomTF>      
      <publishWheelTF>false</publishWheelTF>
      <publishWheelJointState>true</publishWheelJointState>
      <legacyMode>false</legacyMode>
      <rosDebugLevel>na</rosDebugLevel>

    </plugin>
  </gazebo>

  <!-- friccion para ruedas -->
  <gazebo reference="left_wheel">
    <mu1>0.1</mu1>
    <mu2>0.1</mu2>
  </gazebo>
  <gazebo reference="right_wheel">
    <mu1>0.1</mu1>
    <mu2>0.1</mu2>
  </gazebo>


</robot>